Workbook

Sheet Players
A1: Players
A2: Legend: yellow cells = type here. Source: Splash Sports contest export (Aug 25, 2026). 14 players had no first/last name on file in that export - fill those in manually. 'Method' isn't tracked by Splash - fill in manually if you want it.
A4: Player ID | B4: First Name | C4: Last Name | D4: Display Name | E4: Email | F4: Paid? | G4: Method
A6: 2 | B6: Amie | C6: Macdonald | D6: =IF(B6<>"",B6&" "&LEFT(C6,1)&".","") -> Amie M. | E6: amie5550@gmail.com | F6: Y
A7: 53 | B7: Andy | C7: Kempf | D7: =IF(B7<>"",B7&" "&LEFT(C7,1)&".","") -> Andy K. | E7: akempf2@gmail.com | F7: Y
A8: 61 | B8: Bryan | C8: Chauvin | D8: =IF(B8<>"",B8&" "&LEFT(C8,1)&".","") -> Bryan C. | E8: bchauvin73@gmail.com | F8: N
A9: 41 | B9: Bryan | C9: Mink | D9: =IF(B9<>"",B9&" "&LEFT(C9,1)&".","") -> Bryan M. | E9: mink1371@gmail.com | F9: Y
A10: 3 | B10: Charlie | C10: Fadoul | D10: =IF(B10<>"",B10&" "&LEFT(C10,1)&".","") -> Charlie F. | E10: cfadoul@yahoo.com | F10: Y
A11: 58 | B11: Chris | C11: Pearsall | D11: =IF(B11<>"",B11&" "&LEFT(C11,1)&".","") -> Chris P. | E11: christophermpearsall@yahoo.com | F11: N
A12: 4 | B12: Corey | C12: Howard | D12: =IF(B12<>"",B12&" "&LEFT(C12,1)&".","") -> Corey H. | E12: c.howard1865@gmail.com | F12: Y
A13: 57 | B13: Cori | C13: Padgett | D13: =IF(B13<>"",B13&" "&LEFT(C13,1)&".","") -> Cori P. | E13: Corirambow@gmail.com | F13: Y
A14: 6 | B14: Dan | C14: Bonner | D14: =IF(B14<>"",B14&" "&LEFT(C14,1)&".","") -> Dan B. | E14: danielkbonner@gmail.com | F14: Y
A15: 5 | B15: Dan | C15: Lundy | D15: =IF(B15<>"",B15&" "&LEFT(C15,1)&".","") -> Dan L. | E15: 4thdownu@gmail.com | F15: Y
A16: 8 | B16: Dave | C16: Hennington | D16: =IF(B16<>"",B16&" "&LEFT(C16,1)&".","") -> Dave H. | E16: dhennington1975@gmail.com | F16: Y
A17: 7 | B17: David | C17: Young | D17: =IF(B17<>"",B17&" "&LEFT(C17,1)&".","") -> David Y. | E17: dfy582@yahoo.com | F17: Y
... A34: 16 | B34: Josh | C34: Hamilton | D34: =IF(B34<>"",B34&" "&LEFT(C34,1)&".","") -> Josh H. | E34: joshahamilton@gmail.com | F34: Y
A35: 17 | B35: Justin | C35: Sark | D35: =IF(B35<>"",B35&" "&LEFT(C35,1)&".","") -> Justin S. | E35: justin.sark@yahoo.com | F35: Y | G35: Venmo 9/3
A36: 39 | B36: Kaley | C36: Pettenger | D36: =IF(B36<>"",B36&" "&LEFT(C36,1)&".","") -> Kaley P. | E36: klpettenger@aol.com | F36: Y
A37: 49 | B37: Kate | C37: Sark | D37: =IF(B37<>"",B37&" "&LEFT(C37,1)&".","") -> Kate S. | E37: katesark88@gmail.com | F37: Y
A38: 18 | B38: Ken | C38: Lewis | D38: =IF(B38<>"",B38&" "&LEFT(C38,1)&".","") -> Ken L. | E38: mrlouman3@hotmail.com | F38: Y
A39: 50 | B39: Kyle | C39: Wolfersteig | D39: =IF(B39<>"",B39&" "&LEFT(C39,1)&".","") -> Kyle W. | E39: kwolfersteig86@gmail.com | F39: Y
A40: 19 | B40: Lauren | C40: Crowe | D40: =IF(B40<>"",B40&" "&LEFT(C40,1)&".","") -> Lauren C. | E40: lfreed18@gmail.com | F40: Y
A41: 20 | B41: Lauren | C41: Picaut | D41: =IF(B41<>"",B41&" "&LEFT(C41,1)&".","") -> Lauren P. | E41: llandau3@yahoo.com | F41: Y
A42: 21 | B42: Lucas | C42: DeBella | D42: =IF(B42<>"",B42&" "&LEFT(C42,1)&".","") -> Lucas D. | E42: lucasdebella1@gmail.com | F42: Y
A43: 22 | B43: Lynn | C43: Pettenger | D43: =IF(B43<>"",B43&" "&LEFT(C43,1)&".","") -> Lynn P. | E43: kabrmom1214@aol.com | F43: Y
A44: 23 | B44: Martin | C44: Jackson | D44: =IF(B44<>"",B44&" "&LEFT(C44,1)&".","") -> Martin J. | E44: martingjackson@gmail.com | F44: Y
A45: 24 | B45: Matt | C45: Bosang | D45: =IF(B45<>"",B45&" "&LEFT(C45,1)&".","") -> Matt B. | E45: mbosang98@gmail.com | F45: Y
A46: 36 | B46: Matt | C46: Cabrera | D46: =IF(B46<>"",B46&" "&LEFT(C46,1)&".","") -> Matt C. | E46: cabbiem@hotmail.com | F46: Y
A47: 25 | B47: Max | C47: Rosier | D47: =IF(B47<>"",B47&" "&LEFT(C47,1)&".","") -> Max R. | E47: mrosier@imsa.com | F47: Y
... A55: 44 | B55: Richie | C55: Campanaro | D55: =IF(B55<>"",B55&" "&LEFT(C55,1)&".","") -> Richie C. | E55: puckstop62@aol.com | F55: Y
A56: 59 | B56: Roger | C56: Lawson | D56: =IF(B56<>"",B56&" "&LEFT(C56,1)&".","") -> Roger L. | E56: r.lawson234@yahoo.com | F56: Y | G56: Venmo 9/3
A57: 28 | B57: Ryan | C57: Cooper | D57: =IF(B57<>"",B57&" "&LEFT(C57,1)&".","") -> Ryan C. | E57: rcooper2308@yahoo.com | F57: Y
A58: 29 | B58: Ryan | C58: Tilev | D58: =IF(B58<>"",B58&" "&LEFT(C58,1)&".","") -> Ryan T. | E58: ryanstilev@gmail.com | F58: Y
A59: 51 | B59: Stephanie | C59: Campanaro | D59: =IF(B59<>"",B59&" "&LEFT(C59,1)&".","") -> Stephanie C. | E59: stephhass90@gmail.com | F59: Y | G59: PayPal (via Mike C.)
A60: 45 | B60: Taylor | C60: Mowid | D60: =IF(B60<>"",B60&" "&LEFT(C60,1)&".","") -> Taylor M. | E60: taylormowid@gmail.com | F60: Y
A61: 30 | B61: Tom | C61: Bryant | D61: =IF(B61<>"",B61&" "&LEFT(C61,1)&".","") -> Tom B. | E61: j.thomasbryant@yahoo.com | F61: Y
A62: 31 | B62: Tucker | C62: Maletta | D62: =IF(B62<>"",B62&" "&LEFT(C62,1)&".","") -> Tucker M. | E62: ktownbaseball21@gmail.com | F62: Y
A63: 32 | B63: Tye | C63: Edwards | D63: =IF(B63<>"",B63&" "&LEFT(C63,1)&".","") -> Tye E. | E63: tye.edwards@dmedelivers.com | F63: Y
A64: 46 | B64: Tyler | C64: Asher | D64: =IF(B64<>"",B64&" "&LEFT(C64,1)&".","") -> Tyler A. | E64: twacolts@aol.com | F64: Y
A65: 33 | B65: Vicki | C65: Picaut | D65: =IF(B65<>"",B65&" "&LEFT(C65,1)&".","") -> Vicki P. | E65: nukemom@aol.com | F65: Y
...

Sheet Games
A1: Games — 2026 Season
A2: 13 weeks (Thu Sep 3, 2026 - Sat Nov 28, 2026), week before conference championships. Week 1 populated with confirmed matchups. Weeks 2-13: enter as each week's slate is set. TV Channel left blank where not yet confirmed - fill in when announced. Favorite/Underdog: spreads sourced from covers.com, locked in Thursday night before each week's games. True pick'em (0-point spread): the road team is designated the favorite.
A4: Week | B4: Game # | C4: Favorite | D4: Underdog | E4: Date | F4: Time | G4: TV Channel | H4: Home Team
A5: 1 | B5: 1 | C5: Georgia Tech | D5: Colorado | E5: 46268 | F5: 8:00 PM | G5: ESPN | H5: Georgia Tech
A6: 1 | B6: 2 | C6: Eastern Michigan | D6: San Jose State | E6: 46269 | F6: 6:30 PM | G6: ESPN+ | H6: Eastern Michigan
A7: 1 | B7: 3 | C7: James Madison | D7: Liberty | E7: 46270 | F7: 12:00 PM | G7: ESPNU | H7: James Madison
A8: 1 | B8: 4 | C8: Cincinnati | D8: Boston College | E8: 46270 | F8: 3:30 PM | G8: FOX | H8: Cincinnati
A9: 1 | B9: 5 | C9: Duke | D9: Tulane | E9: 46270 | F9: 3:30 PM | G9: ACCN | H9: Duke
A10: 1 | B10: 6 | C10: Auburn | D10: Baylor | E10: 46270 | F10: 3:30 PM | G10: ABC | H10: Neutral - Atlanta, GA (Mercedes-Benz Stadium)
A11: 1 | B11: 7 | C11: Colorado State | D11: Wyoming | E11: 46270 | F11: 6:00 PM | G11: USA | H11: Colorado State
A12: 1 | B12: 8 | C12: LSU | D12: Clemson | E12: 46270 | F12: 7:30 PM | G12: ABC | H12: LSU
A13: 1 | B13: 9 | C13: UNLV | D13: Hawai'i | E13: 46270 | F13: 10:00 PM | G13: CW | H13: Hawai'i
A14: 1 | B14: 10 | C14: UCLA | D14: California | E14: 46270 | F14: 10:30 PM | G14: ESPN | H14: California
A15: 1 | B15: 11 | C15: Western Kentucky | D15: Nevada | E15: 46270 | F15: 10:30 PM | G15: CBSSN | H15: Nevada
A16: 1 | B16: 12 | C16: Ole Miss | D16: Louisville | E16: 46271 | F16: 7:30 PM | G16: ABC | H16: Neutral - Nashville, TN (Nissan Stadium)
... A43: 3 | B43: 13 | C43: James Madison | D43: San Diego State | E43: 46284 | F43: 10:00 PM | G43: CW | H43: San Diego State
A44: 4 | B44: 1
A45: 4 | B45: 2
A46: 4 | B46: 3
A47: 4 | B47: 4
A48: 4 | B48: 5
A49: 4 | B49: 6
A50: 4 | B50: 7
A51: 4 | B51: 8
A52: 4 | B52: 9
A53: 4 | B53: 10
A54: 4 | B54: 11
A55: 4 | B55: 12
... A173: 13 | B173: 13

Sheet Picks_W1
A1: Picks — Week 1
A2: Sorted alphabetically by first name. Yellow cells = type here. Pick columns are dropdowns (Favorite/Underdog team). 2PT columns: enter the game # (1-13) for each of the 3 games this player doubled.
A4: Player | B4: =1&CHAR(10)&Games!C5&" vs "&Games!D5 -> 1 Georgia Tech vs Colorado | C4: =2&CHAR(10)&Games!C6&" vs "&Games!D6 -> 2 Eastern Michigan vs San Jose State | D4: =3&CHAR(10)&Games!C7&" vs "&Games!D7 -> 3 James Madison vs Liberty | E4: =4&CHAR(10)&Games!C8&" vs "&Games!D8 -> 4 Cincinnati vs Boston College | F4: =5&CHAR(10)&Games!C9&" vs "&Games!D9 -> 5 Duke vs Tulane | G4: =6&CHAR(10)&Games!C10&" vs "&Games!D10 -> 6 Auburn vs Baylor | H4: =7&CHAR(10)&Games!C11&" vs "&Games!D11 -> 7 Colorado State vs Wyoming | I4: =8&CHAR(10)&Games!C12&" vs "&Games!D12 -> 8 LSU vs Clemson | J4: =9&CHAR(10)&Games!C13&" vs "&Games!D13 -> 9 UNLV vs Hawai'i | K4: =10&CHAR(10)&Games!C14&" vs "&Games!D14 -> 10 UCLA vs California | L4: =11&CHAR(10)&Games!C15&" vs "&Games!D15 -> 11 Western Kentucky vs Nevada | M4: =12&CHAR(10)&Games!C16&" vs "&Games!D16 -> 12 Ole Miss vs Louisville | N4: =13&CHAR(10)&Games!C17&" vs "&Games!D17 -> 13 SMU vs Florida State | O4: 2PT Game #1 | P4: 2PT Game #2 | Q4: 2PT Game #3 | R4: Tiebreaker Guess | S4: Game 1 Pts | T4: Game 2 Pts | U4: Game 3 Pts | V4: Game 4 Pts | W4: Game 5 Pts | X4: Game 6 Pts | Y4: Game 7 Pts | Z4: Game 8 Pts | AA4: Game 9 Pts | AB4: Game 10 Pts | AC4: Game 11 Pts | AD4: Game 12 Pts | AE4: Game 13 Pts | AF4: Week Total | AG4: TB Diff (helper) | AH4: Player ID (helper) | AI4: G1 Upset Correct? | AJ4: G2 Upset Correct? | AK4: G3 Upset Correct? | AL4: G4 Upset Correct? | AM4: G5 Upset Correct? | AN4: G6 Upset Correct? | AO4: G7 Upset Correct? | AP4: G8 Upset Correct? | AQ4: G9 Upset Correct? | AR4: G10 Upset Correct? | AS4: G11 Upset Correct? | AT4: G12 Upset Correct? | AU4: G13 Upset Correct? | AV4: Weekly Upsets Correct
A6: =INDEX(Players!$D$6:$D$69,MATCH(2,Players!$A$6:$A$69,0)) -> Amie M. | B6: Georgia Tech | C6: Eastern Michigan | D6: James Madison | E6: Cincinnati | F6: Duke | G6: Auburn | H6: Colorado State | I6: LSU | J6: Hawai'i | K6: California | L6: Western Kentucky | M6: Ole Miss | N6: SMU | O6: 4 | P6: 6 | Q6: 8 | R6: 55 | S6: =IF(OR(B6="",Results!B5=""),"",IF(B6=Results!B5,1+IF(OR($O6=1,$P6=1,$Q6=1),1,0),0)) -> 0 | T6: =IF(OR(C6="",Results!C5=""),"",IF(C6=Results!C5,1+IF(OR($O6=2,$P6=2,$Q6=2),1,0),0)) -> 0 | U6: =IF(OR(D6="",Results!D5=""),"",IF(D6=Results!D5,1+IF(OR($O6=3,$P6=3,$Q6=3),1,0),0)) -> 1 | V6: =IF(OR(E6="",Results!E5=""),"",IF(E6=Results!E5,1+IF(OR($O6=4,$P6=4,$Q6=4),1,0),0)) -> 2 | W6: =IF(OR(F6="",Results!F5=""),"",IF(F6=Results!F5,1+IF(OR($O6=5,$P6=5,$Q6=5),1,0),0)) -> 1 | X6: =IF(OR(G6="",Results!G5=""),"",IF(G6=Results!G5,1+IF(OR($O6=6,$P6=6,$Q6=6),1,0),0)) -> 2 | Y6: =IF(OR(H6="",Results!H5=""),"",IF(H6=Results!H5,1+IF(OR($O6=7,$P6=7,$Q6=7),1,0),0)) -> 1 | Z6: =IF(OR(I6="",Results!I5=""),"",IF(I6=Results!I5,1+IF(OR($O6=8,$P6=8,$Q6=8),1,0),0)) -> 2 | AA6: =IF(OR(J6="",Results!J5=""),"",IF(J6=Results!J5,1+IF(OR($O6=9,$P6=9,$Q6=9),1,0),0)) -> 0 | AB6: =IF(OR(K6="",Results!K5=""),"",IF(K6=Results!K5,1+IF(OR($O6=10,$P6=10,$Q6=10),1,0),0)) -> 0 | AC6: =IF(OR(L6="",Results!L5=""),"",IF(L6=Results!L5,1+IF(OR($O6=11,$P6=11,$Q6=11),1,0),0)) -> 0 | AD6: =IF(OR(M6="",Results!M5=""),"",IF(M6=Results!M5,1+IF(OR($O6=12,$P6=12,$Q6=12),1,0),0)) -> 1 | AE6: =IF(OR(N6="",Results!N5=""),"",IF(N6=Results!N5,1+IF(OR($O6=13,$P6=13,$Q6=13),1,0),0)) -> 1 | AF6: =SUM(S6:AE6) -> 11 | AG6: =IF(OR($R6="",Results!O5=""),"",ABS($R6-Results!O5)) -> 4 | AH6: 2 | AI6: =IF(OR(B6="",Results!B5=""),"",IF(AND(B6=Results!B5,Results!B5<>Games!$C$5),1,0)) -> 0 | AJ6: =IF(OR(C6="",Results!C5=""),"",IF(AND(C6=Results!C5,Results!C5<>Games!$C$6),1,0)) -> 0 | AK6: =IF(OR(D6="",Results!D5=""),"",IF(AND(D6=Results!D5,Results!D5<>Games!$C$7),1,0)) -> 0 | AL6: =IF(OR(E6="",Results!E5=""),"",IF(AND(E6=Results!E5,Results!E5<>Games!$C$8),1,0)) -> 0 | AM6: =IF(OR(F6="",Results!F5=""),"",IF(AND(F6=Results!F5,Results!F5<>Games!$C$9),1,0)) -> 0 | AN6: =IF(OR(G6="",Results!G5=""),"",IF(AND(G6=Results!G5,Results!G5<>Games!$C$10),1,0)) -> 0 | AO6: =IF(OR(H6="",Results!H5=""),"",IF(AND(H6=Results!H5,Results!H5<>Games!$C$11),1,0)) -> 0 | AP6: =IF(OR(I6="",Results!I5=""),"",IF(AND(I6=Results!I5,Results!I5<>Games!$C$12),1,0)) -> 0 | AQ6: =IF(OR(J6="",Results!J5=""),"",IF(AND(J6=Results!J5,Results!J5<>Games!$C$13),1,0)) -> 0 | AR6: =IF(OR(K6="",Results!K5=""),"",IF(AND(K6=Results!K5,Results!K5<>Games!$C$14),1,0)) -> 0 | AS6: =IF(OR(L6="",Results!L5=""),"",IF(AND(L6=Results!L5,Results!L5<>Games!$C$15),1,0)) -> 0 | AT6: =IF(OR(M6="",Results!M5=""),"",IF(AND(M6=Results!M5,Results!M5<>Games!$C$16),1,0)) -> 0 | AU6: =IF(OR(N6="",Results!N5=""),"",IF(AND(N6=Results!N5,Results!N5<>Games!$C$17),1,0)) -> 0 | AV6: =SUM(AI6:AU6) -> 0
A7: =INDEX(Players!$D$6:$D$69,MATCH(53,Players!$A$6:$A$69,0)) -> Andy K. | B7: Georgia Tech | C7: Eastern Michigan | D7: James Madison | E7: Cincinnati | F7: Duke | G7: Auburn | H7: Wyoming | I7: LSU | J7: UNLV | K7: California | L7: Nevada | M7: Ole Miss | N7: Florida State | O7: 5 | P7: 6 | Q7: 8 | R7: 54 | S7: =IF(OR(B7="",Results!B5=""),"",IF(B7=Results!B5,1+IF(OR($O7=1,$P7=1,$Q7=1),1,0),0)) -> 0 | T7: =IF(OR(C7="",Results!C5=""),"",IF(C7=Results!C5,1+IF(OR($O7=2,$P7=2,$Q7=2),1,0),0)) -> 0 | U7: =IF(OR(D7="",Results!D5=""),"",IF(D7=Results!D5,1+IF(OR($O7=3,$P7=3,$Q7=3),1,0),0)) -> 1 | V7: =IF(OR(E7="",Results!E5=""),"",IF(E7=Results!E5,1+IF(OR($O7=4,$P7=4,$Q7=4),1,0),0)) -> 1 | W7: =IF(OR(F7="",Results!F5=""),"",IF(F7=Results!F5,1+IF(OR($O7=5,$P7=5,$Q7=5),1,0),0)) -> 2 | X7: =IF(OR(G7="",Results!G5=""),"",IF(G7=Results!G5,1+IF(OR($O7=6,$P7=6,$Q7=6),1,0),0)) -> 2 | Y7: =IF(OR(H7="",Results!H5=""),"",IF(H7=Results!H5,1+IF(OR($O7=7,$P7=7,$Q7=7),1,0),0)) -> 0 | Z7: =IF(OR(I7="",Results!I5=""),"",IF(I7=Results!I5,1+IF(OR($O7=8,$P7=8,$Q7=8),1,0),0)) -> 2 | AA7: =IF(OR(J7="",Results!J5=""),"",IF(J7=Results!J5,1+IF(OR($O7=9,$P7=9,$Q7=9),1,0),0)) -> 1 | AB7: =IF(OR(K7="",Results!K5=""),"",IF(K7=Results!K5,1+IF(OR($O7=10,$P7=10,$Q7=10),1,0),0)) -> 0 | AC7: =IF(OR(L7="",Results!L5=""),"",IF(L7=Results!L5,1+IF(OR($O7=11,$P7=11,$Q7=11),1,0),0)) -> 1 | AD7: =IF(OR(M7="",Results!M5=""),"",IF(M7=Results!M5,1+IF(OR($O7=12,$P7=12,$Q7=12),1,0),0)) -> 1 | AE7: =IF(OR(N7="",Results!N5=""),"",IF(N7=Results!N5,1+IF(OR($O7=13,$P7=13,$Q7=13),1,0),0)) -> 0 | AF7: =SUM(S7:AE7) -> 11 | AG7: =IF(OR($R7="",Results!O5=""),"",ABS($R7-Results!O5)) -> 3 | AH7: 53 | AI7: =IF(OR(B7="",Results!B5=""),"",IF(AND(B7=Results!B5,Results!B5<>Games!$C$5),1,0)) -> 0 | AJ7: =IF(OR(C7="",Results!C5=""),"",IF(AND(C7=Results!C5,Results!C5<>Games!$C$6),1,0)) -> 0 | AK7: =IF(OR(D7="",Results!D5=""),"",IF(AND(D7=Results!D5,Results!D5<>Games!$C$7),1,0)) -> 0 | AL7: =IF(OR(E7="",Results!E5=""),"",IF(AND(E7=Results!E5,Results!E5<>Games!$C$8),1,0)) -> 0 | AM7: =IF(OR(F7="",Results!F5=""),"",IF(AND(F7=Results!F5,Results!F5<>Games!$C$9),1,0)) -> 0 | AN7: =IF(OR(G7="",Results!G5=""),"",IF(AND(G7=Results!G5,Results!G5<>Games!$C$10),1,0)) -> 0 | AO7: =IF(OR(H7="",Results!H5=""),"",IF(AND(H7=Results!H5,Results!H5<>Games!$C$11),1,0)) -> 0 | AP7: =IF(OR(I7="",Results!I5=""),"",IF(AND(I7=Results!I5,Results!I5<>Games!$C$12),1,0)) -> 0 | AQ7: =IF(OR(J7="",Results!J5=""),"",IF(AND(J7=Results!J5,Results!J5<>Games!$C$13),1,0)) -> 0 | AR7: =IF(OR(K7="",Results!K5=""),"",IF(AND(K7=Results!K5,Results!K5<>Games!$C$14),1,0)) -> 0 | AS7: =IF(OR(L7="",Results!L5=""),"",IF(AND(L7=Results!L5,Results!L5<>Games!$C$15),1,0)) -> 1 | AT7: =IF(OR(M7="",Results!M5=""),"",IF(AND(M7=Results!M5,Results!M5<>Games!$C$16),1,0)) -> 0 | AU7: =IF(OR(N7="",Results!N5=""),"",IF(AND(N7=Results!N5,Results!N5<>Games!$C$17),1,0)) -> 0 | AV7: =SUM(AI7:AU7) -> 1
A8: =INDEX(Players!$D$6:$D$69,MATCH(61,Players!$A$6:$A$69,0)) -> Bryan C. | B8: NO PICK | C8: San Jose State | D8: James Madison | E8: Cincinnati | F8: Duke | G8: Auburn | H8: Colorado State | I8: LSU | J8: UNLV | K8: UCLA | L8: Western Kentucky | M8: Louisville | N8: SMU | O8: 6 | P8: 4 | Q8: 8 | R8: 58 | S8: =IF(OR(B8="",Results!B5=""),"",IF(B8=Results!B5,1+IF(OR($O8=1,$P8=1,$Q8=1),1,0),0)) -> 0 | T8: =IF(OR(C8="",Results!C5=""),"",IF(C8=Results!C5,1+IF(OR($O8=2,$P8=2,$Q8=2),1,0),0)) -> 1 | U8: =IF(OR(D8="",Results!D5=""),"",IF(D8=Results!D5,1+IF(OR($O8=3,$P8=3,$Q8=3),1,0),0)) -> 1 | V8: =IF(OR(E8="",Results!E5=""),"",IF(E8=Results!E5,1+IF(OR($O8=4,$P8=4,$Q8=4),1,0),0)) -> 2 | W8: =IF(OR(F8="",Results!F5=""),"",IF(F8=Results!F5,1+IF(OR($O8=5,$P8=5,$Q8=5),1,0),0)) -> 1 | X8: =IF(OR(G8="",Results!G5=""),"",IF(G8=Results!G5,1+IF(OR($O8=6,$P8=6,$Q8=6),1,0),0)) -> 2 | Y8: =IF(OR(H8="",Results!H5=""),"",IF(H8=Results!H5,1+IF(OR($O8=7,$P8=7,$Q8=7),1,0),0)) -> 1 | Z8: =IF(OR(I8="",Results!I5=""),"",IF(I8=Results!I5,1+IF(OR($O8=8,$P8=8,$Q8=8),1,0),0)) -> 2 | AA8: =IF(OR(J8="",Results!J5=""),"",IF(J8=Results!J5,1+IF(OR($O8=9,$P8=9,$Q8=9),1,0),0)) -> 1 | AB8: =IF(OR(K8="",Results!K5=""),"",IF(K8=Results!K5,1+IF(OR($O8=10,$P8=10,$Q8=10),1,0),0)) -> 1 | AC8: =IF(OR(L8="",Results!L5=""),"",IF(L8=Results!L5,1+IF(OR($O8=11,$P8=11,$Q8=11),1,0),0)) -> 0 | AD8: =IF(OR(M8="",Results!M5=""),"",IF(M8=Results!M5,1+IF(OR($O8=12,$P8=12,$Q8=12),1,0),0)) -> 0 | AE8: =IF(OR(N8="",Results!N5=""),"",IF(N8=Results!N5,1+IF(OR($O8=13,$P8=13,$Q8=13),1,0),0)) -> 1 | AF8: =SUM(S8:AE8) -> 13 | AG8: =IF(OR($R8="",Results!O5=""),"",ABS($R8-Results!O5)) -> 7 | AH8: 61 | AI8: =IF(OR(B8="",Results!B5=""),"",IF(AND(B8=Results!B5,Results!B5<>Games!$C$5),1,0)) -> 0 | AJ8: =IF(OR(C8="",Results!C5=""),"",IF(AND(C8=Results!C5,Results!C5<>Games!$C$6),1,0)) -> 1 | AK8: =IF(OR(D8="",Results!D5=""),"",IF(AND(D8=Results!D5,Results!D5<>Games!$C$7),1,0)) -> 0 | AL8: =IF(OR(E8="",Results!E5=""),"",IF(AND(E8=Results!E5,Results!E5<>Games!$C$8),1,0)) -> 0 | AM8: =IF(OR(F8="",Results!F5=""),"",IF(AND(F8=Results!F5,Results!F5<>Games!$C$9),1,0)) -> 0 | AN8: =IF(OR(G8="",Results!G5=""),"",IF(AND(G8=Results!G5,Results!G5<>Games!$C$10),1,0)) -> 0 | AO8: =IF(OR(H8="",Results!H5=""),"",IF(AND(H8=Results!H5,Results!H5<>Games!$C$11),1,0)) -> 0 | AP8: =IF(OR(I8="",Results!I5=""),"",IF(AND(I8=Results!I5,Results!I5<>Games!$C$12),1,0)) -> 0 | AQ8: =IF(OR(J8="",Results!J5=""),"",IF(AND(J8=Results!J5,Results!J5<>Games!$C$13),1,0)) -> 0 | AR8: =IF(OR(K8="",Results!K5=""),"",IF(AND(K8=Results!K5,Results!K5<>Games!$C$14),1,0)) -> 0 | AS8: =IF(OR(L8="",Results!L5=""),"",IF(AND(L8=Results!L5,Results!L5<>Games!$C$15),1,0)) -> 0 | AT8: =IF(OR(M8="",Results!M5=""),"",IF(AND(M8=Results!M5,Results!M5<>Games!$C$16),1,0)) -> 0 | AU8: =IF(OR(N8="",Results!N5=""),"",IF(AND(N8=Results!N5,Results!N5<>Games!$C$17),1,0)) -> 0 | AV8: =SUM(AI8:AU8) -> 1
A9: =INDEX(Players!$D$6:$D$69,MATCH(41,Players!$A$6:$A$69,0)) -> Bryan M. | B9: Georgia Tech | C9: Eastern Michigan | D9: James Madison | E9: Cincinnati | F9: Duke | G9: Auburn | H9: Colorado State | I9: LSU | J9: UNLV | K9: UCLA | L9: Western Kentucky | M9: Ole Miss | N9: SMU | O9: 1 | P9: 4 | Q9: 6 | S9: =IF(OR(B9="",Results!B5=""),"",IF(B9=Results!B5,1+IF(OR($O9=1,$P9=1,$Q9=1),1,0),0)) -> 0 | T9: =IF(OR(C9="",Results!C5=""),"",IF(C9=Results!C5,1+IF(OR($O9=2,$P9=2,$Q9=2),1,0),0)) -> 0 | U9: =IF(OR(D9="",Results!D5=""),"",IF(D9=Results!D5,1+IF(OR($O9=3,$P9=3,$Q9=3),1,0),0)) -> 1 | V9: =IF(OR(E9="",Results!E5=""),"",IF(E9=Results!E5,1+IF(OR($O9=4,$P9=4,$Q9=4),1,0),0)) -> 2 | W9: =IF(OR(F9="",Results!F5=""),"",IF(F9=Results!F5,1+IF(OR($O9=5,$P9=5,$Q9=5),1,0),0)) -> 1 | X9: =IF(OR(G9="",Results!G5=""),"",IF(G9=Results!G5,1+IF(OR($O9=6,$P9=6,$Q9=6),1,0),0)) -> 2 | Y9: =IF(OR(H9="",Results!H5=""),"",IF(H9=Results!H5,1+IF(OR($O9=7,$P9=7,$Q9=7),1,0),0)) -> 1 | Z9: =IF(OR(I9="",Results!I5=""),"",IF(I9=Results!I5,1+IF(OR($O9=8,$P9=8,$Q9=8),1,0),0)) -> 1 | AA9: =IF(OR(J9="",Results!J5=""),"",IF(J9=Results!J5,1+IF(OR($O9=9,$P9=9,$Q9=9),1,0),0)) -> 1 | AB9: =IF(OR(K9="",Results!K5=""),"",IF(K9=Results!K5,1+IF(OR($O9=10,$P9=10,$Q9=10),1,0),0)) -> 1 | AC9: =IF(OR(L9="",Results!L5=""),"",IF(L9=Results!L5,1+IF(OR($O9=11,$P9=11,$Q9=11),1,0),0)) -> 0 | AD9: =IF(OR(M9="",Results!M5=""),"",IF(M9=Results!M5,1+IF(OR($O9=12,$P9=12,$Q9=12),1,0),0)) -> 1 | AE9: =IF(OR(N9="",Results!N5=""),"",IF(N9=Results!N5,1+IF(OR($O9=13,$P9=13,$Q9=13),1,0),0)) -> 1 | AF9: =SUM(S9:AE9) -> 12 | AG9: =IF(OR($R9="",Results!O5=""),"",ABS($R9-Results!O5)) | AH9: 41 | AI9: =IF(OR(B9="",Results!B5=""),"",IF(AND(B9=Results!B5,Results!B5<>Games!$C$5),1,0)) -> 0 | AJ9: =IF(OR(C9="",Results!C5=""),"",IF(AND(C9=Results!C5,Results!C5<>Games!$C$6),1,0)) -> 0 | AK9: =IF(OR(D9="",Results!D5=""),"",IF(AND(D9=Results!D5,Results!D5<>Games!$C$7),1,0)) -> 0 | AL9: =IF(OR(E9="",Results!E5=""),"",IF(AND(E9=Results!E5,Results!E5<>Games!$C$8),1,0)) -> 0 | AM9: =IF(OR(F9="",Results!F5=""),"",IF(AND(F9=Results!F5,Results!F5<>Games!$C$9),1,0)) -> 0 | AN9: =IF(OR(G9="",Results!G5=""),"",IF(AND(G9=Results!G5,Results!G5<>Games!$C$10),1,0)) -> 0 | AO9: =IF(OR(H9="",Results!H5=""),"",IF(AND(H9=Results!H5,Results!H5<>Games!$C$11),1,0)) -> 0 | AP9: =IF(OR(I9="",Results!I5=""),"",IF(AND(I9=Results!I5,Results!I5<>Games!$C$12),1,0)) -> 0 | AQ9: =IF(OR(J9="",Results!J5=""),"",IF(AND(J9=Results!J5,Results!J5<>Games!$C$13),1,0)) -> 0 | AR9: =IF(OR(K9="",Results!K5=""),"",IF(AND(K9=Results!K5,Results!K5<>Games!$C$14),1,0)) -> 0 | AS9: =IF(OR(L9="",Results!L5=""),"",IF(AND(L9=Results!L5,Results!L5<>Games!$C$15),1,0)) -> 0 | AT9: =IF(OR(M9="",Results!M5=""),"",IF(AND(M9=Results!M5,Results!M5<>Games!$C$16),1,0)) -> 0 | AU9: =IF(OR(N9="",Results!N5=""),"",IF(AND(N9=Results!N5,Results!N5<>Games!$C$17),1,0)) -> 0 | AV9: =SUM(AI9:AU9) -> 0
A10: =INDEX(Players!$D$6:$D$69,MATCH(3,Players!$A$6:$A$69,0)) -> Charlie F. | B10: Georgia Tech | C10: Eastern Michigan | D10: James Madison | E10: Boston College | F10: Duke | G10: Auburn | H10: Colorado State | I10: LSU | J10: UNLV | K10: California | L10: Nevada | M10: Ole Miss | N10: SMU | O10: 1 | P10: 12 | Q10: 13 | R10: 52 | S10: =IF(OR(B10="",Results!B5=""),"",IF(B10=Results!B5,1+IF(OR($O10=1,$P10=1,$Q10=1),1,0),0)) -> 0 | T10: =IF(OR(C10="",Results!C5=""),"",IF(C10=Results!C5,1+IF(OR($O10=2,$P10=2,$Q10=2),1,0),0)) -> 0 | U10: =IF(OR(D10="",Results!D5=""),"",IF(D10=Results!D5,1+IF(OR($O10=3,$P10=3,$Q10=3),1,0),0)) -> 1 | V10: =IF(OR(E10="",Results!E5=""),"",IF(E10=Results!E5,1+IF(OR($O10=4,$P10=4,$Q10=4),1,0),0)) -> 0 | W10: =IF(OR(F10="",Results!F5=""),"",IF(F10=Results!F5,1+IF(OR($O10=5,$P10=5,$Q10=5),1,0),0)) -> 1 | X10: =IF(OR(G10="",Results!G5=""),"",IF(G10=Results!G5,1+IF(OR($O10=6,$P10=6,$Q10=6),1,0),0)) -> 1 | Y10: =IF(OR(H10="",Results!H5=""),"",IF(H10=Results!H5,1+IF(OR($O10=7,$P10=7,$Q10=7),1,0),0)) -> 1 | Z10: =IF(OR(I10="",Results!I5=""),"",IF(I10=Results!I5,1+IF(OR($O10=8,$P10=8,$Q10=8),1,0),0)) -> 1 | AA10: =IF(OR(J10="",Results!J5=""),"",IF(J10=Results!J5,1+IF(OR($O10=9,$P10=9,$Q10=9),1,0),0)) -> 1 | AB10: =IF(OR(K10="",Results!K5=""),"",IF(K10=Results!K5,1+IF(OR($O10=10,$P10=10,$Q10=10),1,0),0)) -> 0 | AC10: =IF(OR(L10="",Results!L5=""),"",IF(L10=Results!L5,1+IF(OR($O10=11,$P10=11,$Q10=11),1,0),0)) -> 1 | AD10: =IF(OR(M10="",Results!M5=""),"",IF(M10=Results!M5,1+IF(OR($O10=12,$P10=12,$Q10=12),1,0),0)) -> 2 | AE10: =IF(OR(N10="",Results!N5=""),"",IF(N10=Results!N5,1+IF(OR($O10=13,$P10=13,$Q10=13),1,0),0)) -> 2 | AF10: =SUM(S10:AE10) -> 11 | AG10: =IF(OR($R10="",Results!O5=""),"",ABS($R10-Results!O5)) -> 1 | AH10: 3 | AI10: =IF(OR(B10="",Results!B5=""),"",IF(AND(B10=Results!B5,Results!B5<>Games!$C$5),1,0)) -> 0 | AJ10: =IF(OR(C10="",Results!C5=""),"",IF(AND(C10=Results!C5,Results!C5<>Games!$C$6),1,0)) -> 0 | AK10: =IF(OR(D10="",Results!D5=""),"",IF(AND(D10=Results!D5,Results!D5<>Games!$C$7),1,0)) -> 0 | AL10: =IF(OR(E10="",Results!E5=""),"",IF(AND(E10=Results!E5,Results!E5<>Games!$C$8),1,0)) -> 0 | AM10: =IF(OR(F10="",Results!F5=""),"",IF(AND(F10=Results!F5,Results!F5<>Games!$C$9),1,0)) -> 0 | AN10: =IF(OR(G10="",Results!G5=""),"",IF(AND(G10=Results!G5,Results!G5<>Games!$C$10),1,0)) -> 0 | AO10: =IF(OR(H10="",Results!H5=""),"",IF(AND(H10=Results!H5,Results!H5<>Games!$C$11),1,0)) -> 0 | AP10: =IF(OR(I10="",Results!I5=""),"",IF(AND(I10=Results!I5,Results!I5<>Games!$C$12),1,0)) -> 0 | AQ10: =IF(OR(J10="",Results!J5=""),"",IF(AND(J10=Results!J5,Results!J5<>Games!$C$13),1,0)) -> 0 | AR10: =IF(OR(K10="",Results!K5=""),"",IF(AND(K10=Results!K5,Results!K5<>Games!$C$14),1,0)) -> 0 | AS10: =IF(OR(L10="",Results!L5=""),"",IF(AND(L10=Results!L5,Results!L5<>Games!$C$15),1,0)) -> 1 | AT10: =IF(OR(M10="",Results!M5=""),"",IF(AND(M10=Results!M5,Results!M5<>Games!$C$16),1,0)) -> 0 | AU10: =IF(OR(N10="",Results!N5=""),"",IF(AND(N10=Results!N5,Results!N5<>Games!$C$17),1,0)) -> 0 | AV10: =SUM(AI10:AU10) -> 1
A11: =INDEX(Players!$D$6:$D$69,MATCH(58,Players!$A$6:$A$69,0)) -> Chris P. | B11: Georgia Tech | C11: San Jose State | D11: Liberty | E11: Cincinnati | F11: Duke | G11: Baylor | H11: Colorado State | I11: LSU | J11: UNLV | K11: UCLA | L11: Western Kentucky | M11: Ole Miss | N11: SMU | O11: 1 | P11: 4 | Q11: 8 | R11: 54 | S11: =IF(OR(B11="",Results!B5=""),"",IF(B11=Results!B5,1+IF(OR($O11=1,$P11=1,$Q11=1),1,0),0)) -> 0 | T11: =IF(OR(C11="",Results!C5=""),"",IF(C11=Results!C5,1+IF(OR($O11=2,$P11=2,$Q11=2),1,0),0)) -> 1 | U11: =IF(OR(D11="",Results!D5=""),"",IF(D11=Results!D5,1+IF(OR($O11=3,$P11=3,$Q11=3),1,0),0)) -> 0 | V11: =IF(OR(E11="",Results!E5=""),"",IF(E11=Results!E5,1+IF(OR($O11=4,$P11=4,$Q11=4),1,0),0)) -> 2 | W11: =IF(OR(F11="",Results!F5=""),"",IF(F11=Results!F5,1+IF(OR($O11=5,$P11=5,$Q11=5),1,0),0)) -> 1 | X11: =IF(OR(G11="",Results!G5=""),"",IF(G11=Results!G5,1+IF(OR($O11=6,$P11=6,$Q11=6),1,0),0)) -> 0 | Y11: =IF(OR(H11="",Results!H5=""),"",IF(H11=Results!H5,1+IF(OR($O11=7,$P11=7,$Q11=7),1,0),0)) -> 1 | Z11: =IF(OR(I11="",Results!I5=""),"",IF(I11=Results!I5,1+IF(OR($O11=8,$P11=8,$Q11=8),1,0),0)) -> 2 | AA11: =IF(OR(J11="",Results!J5=""),"",IF(J11=Results!J5,1+IF(OR($O11=9,$P11=9,$Q11=9),1,0),0)) -> 1 | AB11: =IF(OR(K11="",Results!K5=""),"",IF(K11=Results!K5,1+IF(OR($O11=10,$P11=10,$Q11=10),1,0),0)) -> 1 | AC11: =IF(OR(L11="",Results!L5=""),"",IF(L11=Results!L5,1+IF(OR($O11=11,$P11=11,$Q11=11),1,0),0)) -> 0 | AD11: =IF(OR(M11="",Results!M5=""),"",IF(M11=Results!M5,1+IF(OR($O11=12,$P11=12,$Q11=12),1,0),0)) -> 1 | AE11: =IF(OR(N11="",Results!N5=""),"",IF(N11=Results!N5,1+IF(OR($O11=13,$P11=13,$Q11=13),1,0),0)) -> 1 | AF11: =SUM(S11:AE11) -> 11 | AG11: =IF(OR($R11="",Results!O5=""),"",ABS($R11-Results!O5)) -> 3 | AH11: 58 | AI11: =IF(OR(B11="",Results!B5=""),"",IF(AND(B11=Results!B5,Results!B5<>Games!$C$5),1,0)) -> 0 | AJ11: =IF(OR(C11="",Results!C5=""),"",IF(AND(C11=Results!C5,Results!C5<>Games!$C$6),1,0)) -> 1 | AK11: =IF(OR(D11="",Results!D5=""),"",IF(AND(D11=Results!D5,Results!D5<>Games!$C$7),1,0)) -> 0 | AL11: =IF(OR(E11="",Results!E5=""),"",IF(AND(E11=Results!E5,Results!E5<>Games!$C$8),1,0)) -> 0 | AM11: =IF(OR(F11="",Results!F5=""),"",IF(AND(F11=Results!F5,Results!F5<>Games!$C$9),1,0)) -> 0 | AN11: =IF(OR(G11="",Results!G5=""),"",IF(AND(G11=Results!G5,Results!G5<>Games!$C$10),1,0)) -> 0 | AO11: =IF(OR(H11="",Results!H5=""),"",IF(AND(H11=Results!H5,Results!H5<>Games!$C$11),1,0)) -> 0 | AP11: =IF(OR(I11="",Results!I5=""),"",IF(AND(I11=Results!I5,Results!I5<>Games!$C$12),1,0)) -> 0 | AQ11: =IF(OR(J11="",Results!J5=""),"",IF(AND(J11=Results!J5,Results!J5<>Games!$C$13),1,0)) -> 0 | AR11: =IF(OR(K11="",Results!K5=""),"",IF(AND(K11=Results!K5,Results!K5<>Games!$C$14),1,0)) -> 0 | AS11: =IF(OR(L11="",Results!L5=""),"",IF(AND(L11=Results!L5,Results!L5<>Games!$C$15),1,0)) -> 0 | AT11: =IF(OR(M11="",Results!M5=""),"",IF(AND(M11=Results!M5,Results!M5<>Games!$C$16),1,0)) -> 0 | AU11: =IF(OR(N11="",Results!N5=""),"",IF(AND(N11=Results!N5,Results!N5<>Games!$C$17),1,0)) -> 0 | AV11: =SUM(AI11:AU11) -> 1
A12: =INDEX(Players!$D$6:$D$69,MATCH(4,Players!$A$6:$A$69,0)) -> Corey H. | B12: Georgia Tech | C12: Eastern Michigan | D12: James Madison | E12: Cincinnati | F12: Duke | G12: Auburn | H12: Colorado State | I12: LSU | J12: Hawai'i | K12: UCLA | L12: Western Kentucky | M12: Ole Miss | N12: SMU | O12: 5 | P12: 6 | Q12: 8 | R12: 55 | S12: =IF(OR(B12="",Results!B5=""),"",IF(B12=Results!B5,1+IF(OR($O12=1,$P12=1,$Q12=1),1,0),0)) -> 0 | T12: =IF(OR(C12="",Results!C5=""),"",IF(C12=Results!C5,1+IF(OR($O12=2,$P12=2,$Q12=2),1,0),0)) -> 0 | U12: =IF(OR(D12="",Results!D5=""),"",IF(D12=Results!D5,1+IF(OR($O12=3,$P12=3,$Q12=3),1,0),0)) -> 1 | V12: =IF(OR(E12="",Results!E5=""),"",IF(E12=Results!E5,1+IF(OR($O12=4,$P12=4,$Q12=4),1,0),0)) -> 1 | W12: =IF(OR(F12="",Results!F5=""),"",IF(F12=Results!F5,1+IF(OR($O12=5,$P12=5,$Q12=5),1,0),0)) -> 2 | X12: =IF(OR(G12="",Results!G5=""),"",IF(G12=Results!G5,1+IF(OR($O12=6,$P12=6,$Q12=6),1,0),0)) -> 2 | Y12: =IF(OR(H12="",Results!H5=""),"",IF(H12=Results!H5,1+IF(OR($O12=7,$P12=7,$Q12=7),1,0),0)) -> 1 | Z12: =IF(OR(I12="",Results!I5=""),"",IF(I12=Results!I5,1+IF(OR($O12=8,$P12=8,$Q12=8),1,0),0)) -> 2 | AA12: =IF(OR(J12="",Results!J5=""),"",IF(J12=Results!J5,1+IF(OR($O12=9,$P12=9,$Q12=9),1,0),0)) -> 0 | AB12: =IF(OR(K12="",Results!K5=""),"",IF(K12=Results!K5,1+IF(OR($O12=10,$P12=10,$Q12=10),1,0),0)) -> 1 | AC12: =IF(OR(L12="",Results!L5=""),"",IF(L12=Results!L5,1+IF(OR($O12=11,$P12=11,$Q12=11),1,0),0)) -> 0 | AD12: =IF(OR(M12="",Results!M5=""),"",IF(M12=Results!M5,1+IF(OR($O12=12,$P12=12,$Q12=12),1,0),0)) -> 1 | AE12: =IF(OR(N12="",Results!N5=""),"",IF(N12=Results!N5,1+IF(OR($O12=13,$P12=13,$Q12=13),1,0),0)) -> 1 | AF12: =SUM(S12:AE12) -> 12 | AG12: =IF(OR($R12="",Results!O5=""),"",ABS($R12-Results!O5)) -> 4 | AH12: 4 | AI12: =IF(OR(B12="",Results!B5=""),"",IF(AND(B12=Results!B5,Results!B5<>Games!$C$5),1,0)) -> 0 | AJ12: =IF(OR(C12="",Results!C5=""),"",IF(AND(C12=Results!C5,Results!C5<>Games!$C$6),1,0)) -> 0 | AK12: =IF(OR(D12="",Results!D5=""),"",IF(AND(D12=Results!D5,Results!D5<>Games!$C$7),1,0)) -> 0 | AL12: =IF(OR(E12="",Results!E5=""),"",IF(AND(E12=Results!E5,Results!E5<>Games!$C$8),1,0)) -> 0 | AM12: =IF(OR(F12="",Results!F5=""),"",IF(AND(F12=Results!F5,Results!F5<>Games!$C$9),1,0)) -> 0 | AN12: =IF(OR(G12="",Results!G5=""),"",IF(AND(G12=Results!G5,Results!G5<>Games!$C$10),1,0)) -> 0 | AO12: =IF(OR(H12="",Results!H5=""),"",IF(AND(H12=Results!H5,Results!H5<>Games!$C$11),1,0)) -> 0 | AP12: =IF(OR(I12="",Results!I5=""),"",IF(AND(I12=Results!I5,Results!I5<>Games!$C$12),1,0)) -> 0 | AQ12: =IF(OR(J12="",Results!J5=""),"",IF(AND(J12=Results!J5,Results!J5<>Games!$C$13),1,0)) -> 0 | AR12: =IF(OR(K12="",Results!K5=""),"",IF(AND(K12=Results!K5,Results!K5<>Games!$C$14),1,0)) -> 0 | AS12: =IF(OR(L12="",Results!L5=""),"",IF(AND(L12=Results!L5,Results!L5<>Games!$C$15),1,0)) -> 0 | AT12: =IF(OR(M12="",Results!M5=""),"",IF(AND(M12=Results!M5,Results!M5<>Games!$C$16),1,0)) -> 0 | AU12: =IF(OR(N12="",Results!N5=""),"",IF(AND(N12=Results!N5,Results!N5<>Games!$C$17),1,0)) -> 0 | AV12: =SUM(AI12:AU12) -> 0
A13: =INDEX(Players!$D$6:$D$69,MATCH(57,Players!$A$6:$A$69,0)) -> Cori P. | B13: Georgia Tech | C13: San Jose State | D13: James Madison | E13: Cincinnati | F13: Duke | G13: Auburn | H13: Wyoming | I13: Clemson | J13: Hawai'i | K13: California | L13: Western Kentucky | M13: Ole Miss | N13: SMU | O13: 3 | P13: 11 | Q13: 12 | S13: =IF(OR(B13="",Results!B5=""),"",IF(B13=Results!B5,1+IF(OR($O13=1,$P13=1,$Q13=1),1,0),0)) -> 0 | T13: =IF(OR(C13="",Results!C5=""),"",IF(C13=Results!C5,1+IF(OR($O13=2,$P13=2,$Q13=2),1,0),0)) -> 1 | U13: =IF(OR(D13="",Results!D5=""),"",IF(D13=Results!D5,1+IF(OR($O13=3,$P13=3,$Q13=3),1,0),0)) -> 2 | V13: =IF(OR(E13="",Results!E5=""),"",IF(E13=Results!E5,1+IF(OR($O13=4,$P13=4,$Q13=4),1,0),0)) -> 1 | W13: =IF(OR(F13="",Results!F5=""),"",IF(F13=Results!F5,1+IF(OR($O13=5,$P13=5,$Q13=5),1,0),0)) -> 1 | X13: =IF(OR(G13="",Results!G5=""),"",IF(G13=Results!G5,1+IF(OR($O13=6,$P13=6,$Q13=6),1,0),0)) -> 1 | Y13: =IF(OR(H13="",Results!H5=""),"",IF(H13=Results!H5,1+IF(OR($O13=7,$P13=7,$Q13=7),1,0),0)) -> 0 | Z13: =IF(OR(I13="",Results!I5=""),"",IF(I13=Results!I5,1+IF(OR($O13=8,$P13=8,$Q13=8),1,0),0)) -> 0 | AA13: =IF(OR(J13="",Results!J5=""),"",IF(J13=Results!J5,1+IF(OR($O13=9,$P13=9,$Q13=9),1,0),0)) -> 0 | AB13: =IF(OR(K13="",Results!K5=""),"",IF(K13=Results!K5,1+IF(OR($O13=10,$P13=10,$Q13=10),1,0),0)) -> 0 | AC13: =IF(OR(L13="",Results!L5=""),"",IF(L13=Results!L5,1+IF(OR($O13=11,$P13=11,$Q13=11),1,0),0)) -> 0 | AD13: =IF(OR(M13="",Results!M5=""),"",IF(M13=Results!M5,1+IF(OR($O13=12,$P13=12,$Q13=12),1,0),0)) -> 2 | AE13: =IF(OR(N13="",Results!N5=""),"",IF(N13=Results!N5,1+IF(OR($O13=13,$P13=13,$Q13=13),1,0),0)) -> 1 | AF13: =SUM(S13:AE13) -> 9 | AG13: =IF(OR($R13="",Results!O5=""),"",ABS($R13-Results!O5)) | AH13: 57 | AI13: =IF(OR(B13="",Results!B5=""),"",IF(AND(B13=Results!B5,Results!B5<>Games!$C$5),1,0)) -> 0 | AJ13: =IF(OR(C13="",Results!C5=""),"",IF(AND(C13=Results!C5,Results!C5<>Games!$C$6),1,0)) -> 1 | AK13: =IF(OR(D13="",Results!D5=""),"",IF(AND(D13=Results!D5,Results!D5<>Games!$C$7),1,0)) -> 0 | AL13: =IF(OR(E13="",Results!E5=""),"",IF(AND(E13=Results!E5,Results!E5<>Games!$C$8),1,0)) -> 0 | AM13: =IF(OR(F13="",Results!F5=""),"",IF(AND(F13=Results!F5,Results!F5<>Games!$C$9),1,0)) -> 0 | AN13: =IF(OR(G13="",Results!G5=""),"",IF(AND(G13=Results!G5,Results!G5<>Games!$C$10),1,0)) -> 0 | AO13: =IF(OR(H13="",Results!H5=""),"",IF(AND(H13=Results!H5,Results!H5<>Games!$C$11),1,0)) -> 0 | AP13: =IF(OR(I13="",Results!I5=""),"",IF(AND(I13=Results!I5,Results!I5<>Games!$C$12),1,0)) -> 0 | AQ13: =IF(OR(J13="",Results!J5=""),"",IF(AND(J13=Results!J5,Results!J5<>Games!$C$13),1,0)) -> 0 | AR13: =IF(OR(K13="",Results!K5=""),"",IF(AND(K13=Results!K5,Results!K5<>Games!$C$14),1,0)) -> 0 | AS13: =IF(OR(L13="",Results!L5=""),"",IF(AND(L13=Results!L5,Results!L5<>Games!$C$15),1,0)) -> 0 | AT13: =IF(OR(M13="",Results!M5=""),"",IF(AND(M13=Results!M5,Results!M5<>Games!$C$16),1,0)) -> 0 | AU13: =IF(OR(N13="",Results!N5=""),"",IF(AND(N13=Results!N5,Results!N5<>Games!$C$17),1,0)) -> 0 | AV13: =SUM(AI13:AU13) -> 1
A14: =INDEX(Players!$D$6:$D$69,MATCH(6,Players!$A$6:$A$69,0)) -> Dan B. | B14: Georgia Tech | C14: Eastern Michigan | D14: James Madison | E14: Cincinnati | F14: Duke | G14: Auburn | H14: Colorado State | I14: LSU | J14: UNLV | K14: UCLA | L14: Western Kentucky | M14: Louisville | N14: Florida State | O14: 1 | P14: 4 | Q14: 5 | R14: 47 | S14: =IF(OR(B14="",Results!B5=""),"",IF(B14=Results!B5,1+IF(OR($O14=1,$P14=1,$Q14=1),1,0),0)) -> 0 | T14: =IF(OR(C14="",Results!C5=""),"",IF(C14=Results!C5,1+IF(OR($O14=2,$P14=2,$Q14=2),1,0),0)) -> 0 | U14: =IF(OR(D14="",Results!D5=""),"",IF(D14=Results!D5,1+IF(OR($O14=3,$P14=3,$Q14=3),1,0),0)) -> 1 | V14: =IF(OR(E14="",Results!E5=""),"",IF(E14=Results!E5,1+IF(OR($O14=4,$P14=4,$Q14=4),1,0),0)) -> 2 | W14: =IF(OR(F14="",Results!F5=""),"",IF(F14=Results!F5,1+IF(OR($O14=5,$P14=5,$Q14=5),1,0),0)) -> 2 | X14: =IF(OR(G14="",Results!G5=""),"",IF(G14=Results!G5,1+IF(OR($O14=6,$P14=6,$Q14=6),1,0),0)) -> 1 | Y14: =IF(OR(H14="",Results!H5=""),"",IF(H14=Results!H5,1+IF(OR($O14=7,$P14=7,$Q14=7),1,0),0)) -> 1 | Z14: =IF(OR(I14="",Results!I5=""),"",IF(I14=Results!I5,1+IF(OR($O14=8,$P14=8,$Q14=8),1,0),0)) -> 1 | AA14: =IF(OR(J14="",Results!J5=""),"",IF(J14=Results!J5,1+IF(OR($O14=9,$P14=9,$Q14=9),1,0),0)) -> 1 | AB14: =IF(OR(K14="",Results!K5=""),"",IF(K14=Results!K5,1+IF(OR($O14=10,$P14=10,$Q14=10),1,0),0)) -> 1 | AC14: =IF(OR(L14="",Results!L5=""),"",IF(L14=Results!L5,1+IF(OR($O14=11,$P14=11,$Q14=11),1,0),0)) -> 0 | AD14: =IF(OR(M14="",Results!M5=""),"",IF(M14=Results!M5,1+IF(OR($O14=12,$P14=12,$Q14=12),1,0),0)) -> 0 | AE14: =IF(OR(N14="",Results!N5=""),"",IF(N14=Results!N5,1+IF(OR($O14=13,$P14=13,$Q14=13),1,0),0)) -> 0 | AF14: =SUM(S14:AE14) -> 10 | AG14: =IF(OR($R14="",Results!O5=""),"",ABS($R14-Results!O5)) -> 4 | AH14: 6 | AI14: =IF(OR(B14="",Results!B5=""),"",IF(AND(B14=Results!B5,Results!B5<>Games!$C$5),1,0)) -> 0 | AJ14: =IF(OR(C14="",Results!C5=""),"",IF(AND(C14=Results!C5,Results!C5<>Games!$C$6),1,0)) -> 0 | AK14: =IF(OR(D14="",Results!D5=""),"",IF(AND(D14=Results!D5,Results!D5<>Games!$C$7),1,0)) -> 0 | AL14: =IF(OR(E14="",Results!E5=""),"",IF(AND(E14=Results!E5,Results!E5<>Games!$C$8),1,0)) -> 0 | AM14: =IF(OR(F14="",Results!F5=""),"",IF(AND(F14=Results!F5,Results!F5<>Games!$C$9),1,0)) -> 0 | AN14: =IF(OR(G14="",Results!G5=""),"",IF(AND(G14=Results!G5,Results!G5<>Games!$C$10),1,0)) -> 0 | AO14: =IF(OR(H14="",Results!H5=""),"",IF(AND(H14=Results!H5,Results!H5<>Games!$C$11),1,0)) -> 0 | AP14: =IF(OR(I14="",Results!I5=""),"",IF(AND(I14=Results!I5,Results!I5<>Games!$C$12),1,0)) -> 0 | AQ14: =IF(OR(J14="",Results!J5=""),"",IF(AND(J14=Results!J5,Results!J5<>Games!$C$13),1,0)) -> 0 | AR14: =IF(OR(K14="",Results!K5=""),"",IF(AND(K14=Results!K5,Results!K5<>Games!$C$14),1,0)) -> 0 | AS14: =IF(OR(L14="",Results!L5=""),"",IF(AND(L14=Results!L5,Results!L5<>Games!$C$15),1,0)) -> 0 | AT14: =IF(OR(M14="",Results!M5=""),"",IF(AND(M14=Results!M5,Results!M5<>Games!$C$16),1,0)) -> 0 | AU14: =IF(OR(N14="",Results!N5=""),"",IF(AND(N14=Results!N5,Results!N5<>Games!$C$17),1,0)) -> 0 | AV14: =SUM(AI14:AU14) -> 0
A15: =INDEX(Players!$D$6:$D$69,MATCH(5,Players!$A$6:$A$69,0)) -> Dan L. | B15: Georgia Tech | C15: Eastern Michigan | D15: James Madison | E15: Cincinnati | F15: Duke | G15: Auburn | H15: Colorado State | I15: LSU | J15: UNLV | K15: UCLA | L15: Western Kentucky | M15: Ole Miss | N15: SMU | O15: 4 | P15: 5 | Q15: 8 | R15: 51 | S15: =IF(OR(B15="",Results!B5=""),"",IF(B15=Results!B5,1+IF(OR($O15=1,$P15=1,$Q15=1),1,0),0)) -> 0 | T15: =IF(OR(C15="",Results!C5=""),"",IF(C15=Results!C5,1+IF(OR($O15=2,$P15=2,$Q15=2),1,0),0)) -> 0 | U15: =IF(OR(D15="",Results!D5=""),"",IF(D15=Results!D5,1+IF(OR($O15=3,$P15=3,$Q15=3),1,0),0)) -> 1 | V15: =IF(OR(E15="",Results!E5=""),"",IF(E15=Results!E5,1+IF(OR($O15=4,$P15=4,$Q15=4),1,0),0)) -> 2 | W15: =IF(OR(F15="",Results!F5=""),"",IF(F15=Results!F5,1+IF(OR($O15=5,$P15=5,$Q15=5),1,0),0)) -> 2 | X15: =IF(OR(G15="",Results!G5=""),"",IF(G15=Results!G5,1+IF(OR($O15=6,$P15=6,$Q15=6),1,0),0)) -> 1 | Y15: =IF(OR(H15="",Results!H5=""),"",IF(H15=Results!H5,1+IF(OR($O15=7,$P15=7,$Q15=7),1,0),0)) -> 1 | Z15: =IF(OR(I15="",Results!I5=""),"",IF(I15=Results!I5,1+IF(OR($O15=8,$P15=8,$Q15=8),1,0),0)) -> 2 | AA15: =IF(OR(J15="",Results!J5=""),"",IF(J15=Results!J5,1+IF(OR($O15=9,$P15=9,$Q15=9),1,0),0)) -> 1 | AB15: =IF(OR(K15="",Results!K5=""),"",IF(K15=Results!K5,1+IF(OR($O15=10,$P15=10,$Q15=10),1,0),0)) -> 1 | AC15: =IF(OR(L15="",Results!L5=""),"",IF(L15=Results!L5,1+IF(OR($O15=11,$P15=11,$Q15=11),1,0),0)) -> 0 | AD15: =IF(OR(M15="",Results!M5=""),"",IF(M15=Results!M5,1+IF(OR($O15=12,$P15=12,$Q15=12),1,0),0)) -> 1 | AE15: =IF(OR(N15="",Results!N5=""),"",IF(N15=Results!N5,1+IF(OR($O15=13,$P15=13,$Q15=13),1,0),0)) -> 1 | AF15: =SUM(S15:AE15) -> 13 | AG15: =IF(OR($R15="",Results!O5=""),"",ABS($R15-Results!O5)) -> 0 | AH15: 5 | AI15: =IF(OR(B15="",Results!B5=""),"",IF(AND(B15=Results!B5,Results!B5<>Games!$C$5),1,0)) -> 0 | AJ15: =IF(OR(C15="",Results!C5=""),"",IF(AND(C15=Results!C5,Results!C5<>Games!$C$6),1,0)) -> 0 | AK15: =IF(OR(D15="",Results!D5=""),"",IF(AND(D15=Results!D5,Results!D5<>Games!$C$7),1,0)) -> 0 | AL15: =IF(OR(E15="",Results!E5=""),"",IF(AND(E15=Results!E5,Results!E5<>Games!$C$8),1,0)) -> 0 | AM15: =IF(OR(F15="",Results!F5=""),"",IF(AND(F15=Results!F5,Results!F5<>Games!$C$9),1,0)) -> 0 | AN15: =IF(OR(G15="",Results!G5=""),"",IF(AND(G15=Results!G5,Results!G5<>Games!$C$10),1,0)) -> 0 | AO15: =IF(OR(H15="",Results!H5=""),"",IF(AND(H15=Results!H5,Results!H5<>Games!$C$11),1,0)) -> 0 | AP15: =IF(OR(I15="",Results!I5=""),"",IF(AND(I15=Results!I5,Results!I5<>Games!$C$12),1,0)) -> 0 | AQ15: =IF(OR(J15="",Results!J5=""),"",IF(AND(J15=Results!J5,Results!J5<>Games!$C$13),1,0)) -> 0 | AR15: =IF(OR(K15="",Results!K5=""),"",IF(AND(K15=Results!K5,Results!K5<>Games!$C$14),1,0)) -> 0 | AS15: =IF(OR(L15="",Results!L5=""),"",IF(AND(L15=Results!L5,Results!L5<>Games!$C$15),1,0)) -> 0 | AT15: =IF(OR(M15="",Results!M5=""),"",IF(AND(M15=Results!M5,Results!M5<>Games!$C$16),1,0)) -> 0 | AU15: =IF(OR(N15="",Results!N5=""),"",IF(AND(N15=Results!N5,Results!N5<>Games!$C$17),1,0)) -> 0 | AV15: =SUM(AI15:AU15) -> 0
A16: =INDEX(Players!$D$6:$D$69,MATCH(8,Players!$A$6:$A$69,0)) -> Dave H. | B16: Georgia Tech | C16: San Jose State | D16: James Madison | E16: Cincinnati | F16: Duke | G16: Auburn | H16: Wyoming | I16: LSU | J16: UNLV | K16: UCLA | L16: Western Kentucky | M16: Ole Miss | N16: Florida State | O16: 1 | P16: 8 | Q16: 9 | R16: 66 | S16: =IF(OR(B16="",Results!B5=""),"",IF(B16=Results!B5,1+IF(OR($O16=1,$P16=1,$Q16=1),1,0),0)) -> 0 | T16: =IF(OR(C16="",Results!C5=""),"",IF(C16=Results!C5,1+IF(OR($O16=2,$P16=2,$Q16=2),1,0),0)) -> 1 | U16: =IF(OR(D16="",Results!D5=""),"",IF(D16=Results!D5,1+IF(OR($O16=3,$P16=3,$Q16=3),1,0),0)) -> 1 | V16: =IF(OR(E16="",Results!E5=""),"",IF(E16=Results!E5,1+IF(OR($O16=4,$P16=4,$Q16=4),1,0),0)) -> 1 | W16: =IF(OR(F16="",Results!F5=""),"",IF(F16=Results!F5,1+IF(OR($O16=5,$P16=5,$Q16=5),1,0),0)) -> 1 | X16: =IF(OR(G16="",Results!G5=""),"",IF(G16=Results!G5,1+IF(OR($O16=6,$P16=6,$Q16=6),1,0),0)) -> 1 | Y16: =IF(OR(H16="",Results!H5=""),"",IF(H16=Results!H5,1+IF(OR($O16=7,$P16=7,$Q16=7),1,0),0)) -> 0 | Z16: =IF(OR(I16="",Results!I5=""),"",IF(I16=Results!I5,1+IF(OR($O16=8,$P16=8,$Q16=8),1,0),0)) -> 2 | AA16: =IF(OR(J16="",Results!J5=""),"",IF(J16=Results!J5,1+IF(OR($O16=9,$P16=9,$Q16=9),1,0),0)) -> 2 | AB16: =IF(OR(K16="",Results!K5=""),"",IF(K16=Results!K5,1+IF(OR($O16=10,$P16=10,$Q16=10),1,0),0)) -> 1 | AC16: =IF(OR(L16="",Results!L5=""),"",IF(L16=Results!L5,1+IF(OR($O16=11,$P16=11,$Q16=11),1,0),0)) -> 0 | AD16: =IF(OR(M16="",Results!M5=""),"",IF(M16=Results!M5,1+IF(OR($O16=12,$P16=12,$Q16=12),1,0),0)) -> 1 | AE16: =IF(OR(N16="",Results!N5=""),"",IF(N16=Results!N5,1+IF(OR($O16=13,$P16=13,$Q16=13),1,0),0)) -> 0 | AF16: =SUM(S16:AE16) -> 11 | AG16: =IF(OR($R16="",Results!O5=""),"",ABS($R16-Results!O5)) -> 15 | AH16: 8 | AI16: =IF(OR(B16="",Results!B5=""),"",IF(AND(B16=Results!B5,Results!B5<>Games!$C$5),1,0)) -> 0 | AJ16: =IF(OR(C16="",Results!C5=""),"",IF(AND(C16=Results!C5,Results!C5<>Games!$C$6),1,0)) -> 1 | AK16: =IF(OR(D16="",Results!D5=""),"",IF(AND(D16=Results!D5,Results!D5<>Games!$C$7),1,0)) -> 0 | AL16: =IF(OR(E16="",Results!E5=""),"",IF(AND(E16=Results!E5,Results!E5<>Games!$C$8),1,0)) -> 0 | AM16: =IF(OR(F16="",Results!F5=""),"",IF(AND(F16=Results!F5,Results!F5<>Games!$C$9),1,0)) -> 0 | AN16: =IF(OR(G16="",Results!G5=""),"",IF(AND(G16=Results!G5,Results!G5<>Games!$C$10),1,0)) -> 0 | AO16: =IF(OR(H16="",Results!H5=""),"",IF(AND(H16=Results!H5,Results!H5<>Games!$C$11),1,0)) -> 0 | AP16: =IF(OR(I16="",Results!I5=""),"",IF(AND(I16=Results!I5,Results!I5<>Games!$C$12),1,0)) -> 0 | AQ16: =IF(OR(J16="",Results!J5=""),"",IF(AND(J16=Results!J5,Results!J5<>Games!$C$13),1,0)) -> 0 | AR16: =IF(OR(K16="",Results!K5=""),"",IF(AND(K16=Results!K5,Results!K5<>Games!$C$14),1,0)) -> 0 | AS16: =IF(OR(L16="",Results!L5=""),"",IF(AND(L16=Results!L5,Results!L5<>Games!$C$15),1,0)) -> 0 | AT16: =IF(OR(M16="",Results!M5=""),"",IF(AND(M16=Results!M5,Results!M5<>Games!$C$16),1,0)) -> 0 | AU16: =IF(OR(N16="",Results!N5=""),"",IF(AND(N16=Results!N5,Results!N5<>Games!$C$17),1,0)) -> 0 | AV16: =SUM(AI16:AU16) -> 1
A17: =INDEX(Players!$D$6:$D$69,MATCH(7,Players!$A$6:$A$69,0)) -> David Y. | B17: Georgia Tech | C17: Eastern Michigan | D17: James Madison | E17: Cincinnati | F17: Duke | G17: Auburn | H17: Colorado State | I17: LSU | J17: UNLV | K17: UCLA | L17: Western Kentucky | M17: Ole Miss | N17: SMU | O17: 4 | P17: 8 | Q17: 12 | R17: 58 | S17: =IF(OR(B17="",Results!B5=""),"",IF(B17=Results!B5,1+IF(OR($O17=1,$P17=1,$Q17=1),1,0),0)) -> 0 | T17: =IF(OR(C17="",Results!C5=""),"",IF(C17=Results!C5,1+IF(OR($O17=2,$P17=2,$Q17=2),1,0),0)) -> 0 | U17: =IF(OR(D17="",Results!D5=""),"",IF(D17=Results!D5,1+IF(OR($O17=3,$P17=3,$Q17=3),1,0),0)) -> 1 | V17: =IF(OR(E17="",Results!E5=""),"",IF(E17=Results!E5,1+IF(OR($O17=4,$P17=4,$Q17=4),1,0),0)) -> 2 | W17: =IF(OR(F17="",Results!F5=""),"",IF(F17=Results!F5,1+IF(OR($O17=5,$P17=5,$Q17=5),1,0),0)) -> 1 | X17: =IF(OR(G17="",Results!G5=""),"",IF(G17=Results!G5,1+IF(OR($O17=6,$P17=6,$Q17=6),1,0),0)) -> 1 | Y17: =IF(OR(H17="",Results!H5=""),"",IF(H17=Results!H5,1+IF(OR($O17=7,$P17=7,$Q17=7),1,0),0)) -> 1 | Z17: =IF(OR(I17="",Results!I5=""),"",IF(I17=Results!I5,1+IF(OR($O17=8,$P17=8,$Q17=8),1,0),0)) -> 2 | AA17: =IF(OR(J17="",Results!J5=""),"",IF(J17=Results!J5,1+IF(OR($O17=9,$P17=9,$Q17=9),1,0),0)) -> 1 | AB17: =IF(OR(K17="",Results!K5=""),"",IF(K17=Results!K5,1+IF(OR($O17=10,$P17=10,$Q17=10),1,0),0)) -> 1 | AC17: =IF(OR(L17="",Results!L5=""),"",IF(L17=Results!L5,1+IF(OR($O17=11,$P17=11,$Q17=11),1,0),0)) -> 0 | AD17: =IF(OR(M17="",Results!M5=""),"",IF(M17=Results!M5,1+IF(OR($O17=12,$P17=12,$Q17=12),1,0),0)) -> 2 | AE17: =IF(OR(N17="",Results!N5=""),"",IF(N17=Results!N5,1+IF(OR($O17=13,$P17=13,$Q17=13),1,0),0)) -> 1 | AF17: =SUM(S17:AE17) -> 13 | AG17: =IF(OR($R17="",Results!O5=""),"",ABS($R17-Results!O5)) -> 7 | AH17: 7 | AI17: =IF(OR(B17="",Results!B5=""),"",IF(AND(B17=Results!B5,Results!B5<>Games!$C$5),1,0)) -> 0 | AJ17: =IF(OR(C17="",Results!C5=""),"",IF(AND(C17=Results!C5,Results!C5<>Games!$C$6),1,0)) -> 0 | AK17: =IF(OR(D17="",Results!D5=""),"",IF(AND(D17=Results!D5,Results!D5<>Games!$C$7),1,0)) -> 0 | AL17: =IF(OR(E17="",Results!E5=""),"",IF(AND(E17=Results!E5,Results!E5<>Games!$C$8),1,0)) -> 0 | AM17: =IF(OR(F17="",Results!F5=""),"",IF(AND(F17=Results!F5,Results!F5<>Games!$C$9),1,0)) -> 0 | AN17: =IF(OR(G17="",Results!G5=""),"",IF(AND(G17=Results!G5,Results!G5<>Games!$C$10),1,0)) -> 0 | AO17: =IF(OR(H17="",Results!H5=""),"",IF(AND(H17=Results!H5,Results!H5<>Games!$C$11),1,0)) -> 0 | AP17: =IF(OR(I17="",Results!I5=""),"",IF(AND(I17=Results!I5,Results!I5<>Games!$C$12),1,0)) -> 0 | AQ17: =IF(OR(J17="",Results!J5=""),"",IF(AND(J17=Results!J5,Results!J5<>Games!$C$13),1,0)) -> 0 | AR17: =IF(OR(K17="",Results!K5=""),"",IF(AND(K17=Results!K5,Results!K5<>Games!$C$14),1,0)) -> 0 | AS17: =IF(OR(L17="",Results!L5=""),"",IF(AND(L17=Results!L5,Results!L5<>Games!$C$15),1,0)) -> 0 | AT17: =IF(OR(M17="",Results!M5=""),"",IF(AND(M17=Results!M5,Results!M5<>Games!$C$16),1,0)) -> 0 | AU17: =IF(OR(N17="",Results!N5=""),"",IF(AND(N17=Results!N5,Results!N5<>Games!$C$17),1,0)) -> 0 | AV17: =SUM(AI17:AU17) -> 0
A18: =INDEX(Players!$D$6:$D$69,MATCH(37,Players!$A$6:$A$69,0)) -> Dino C. | B18: Georgia Tech | C18: Eastern Michigan | D18: James Madison | E18: Boston College | F18: Duke | G18: Auburn | H18: Colorado State | I18: Clemson | J18: Hawai'i | K18: UCLA | L18: Western Kentucky | M18: Ole Miss | N18: Florida State | O18: 4 | P18: 5 | Q18: 12 | R18: 47 | S18: =IF(OR(B18="",Results!B5=""),"",IF(B18=Results!B5,1+IF(OR($O18=1,$P18=1,$Q18=1),1,0),0)) -> 0 | T18: =IF(OR(C18="",Results!C5=""),"",IF(C18=Results!C5,1+IF(OR($O18=2,$P18=2,$Q18=2),1,0),0)) -> 0 | U18: =IF(OR(D18="",Results!D5=""),"",IF(D18=Results!D5,1+IF(OR($O18=3,$P18=3,$Q18=3),1,0),0)) -> 1 | V18: =IF(OR(E18="",Results!E5=""),"",IF(E18=Results!E5,1+IF(OR($O18=4,$P18=4,$Q18=4),1,0),0)) -> 0 | W18: =IF(OR(F18="",Results!F5=""),"",IF(F18=Results!F5,1+IF(OR($O18=5,$P18=5,$Q18=5),1,0),0)) -> 2 | X18: =IF(OR(G18="",Results!G5=""),"",IF(G18=Results!G5,1+IF(OR($O18=6,$P18=6,$Q18=6),1,0),0)) -> 1 | Y18: =IF(OR(H18="",Results!H5=""),"",IF(H18=Results!H5,1+IF(OR($O18=7,$P18=7,$Q18=7),1,0),0)) -> 1 | Z18: =IF(OR(I18="",Results!I5=""),"",IF(I18=Results!I5,1+IF(OR($O18=8,$P18=8,$Q18=8),1,0),0)) -> 0 | AA18: =IF(OR(J18="",Results!J5=""),"",IF(J18=Results!J5,1+IF(OR($O18=9,$P18=9,$Q18=9),1,0),0)) -> 0 | AB18: =IF(OR(K18="",Results!K5=""),"",IF(K18=Results!K5,1+IF(OR($O18=10,$P18=10,$Q18=10),1,0),0)) -> 1 | AC18: =IF(OR(L18="",Results!L5=""),"",IF(L18=Results!L5,1+IF(OR($O18=11,$P18=11,$Q18=11),1,0),0)) -> 0 | AD18: =IF(OR(M18="",Results!M5=""),"",IF(M18=Results!M5,1+IF(OR($O18=12,$P18=12,$Q18=12),1,0),0)) -> 2 | AE18: =IF(OR(N18="",Results!N5=""),"",IF(N18=Results!N5,1+IF(OR($O18=13,$P18=13,$Q18=13),1,0),0)) -> 0 | AF18: =SUM(S18:AE18) -> 8 | AG18: =IF(OR($R18="",Results!O5=""),"",ABS($R18-Results!O5)) -> 4 | AH18: 37 | AI18: =IF(OR(B18="",Results!B5=""),"",IF(AND(B18=Results!B5,Results!B5<>Games!$C$5),1,0)) -> 0 | AJ18: =IF(OR(C18="",Results!C5=""),"",IF(AND(C18=Results!C5,Results!C5<>Games!$C$6),1,0)) -> 0 | AK18: =IF(OR(D18="",Results!D5=""),"",IF(AND(D18=Results!D5,Results!D5<>Games!$C$7),1,0)) -> 0 | AL18: =IF(OR(E18="",Results!E5=""),"",IF(AND(E18=Results!E5,Results!E5<>Games!$C$8),1,0)) -> 0 | AM18: =IF(OR(F18="",Results!F5=""),"",IF(AND(F18=Results!F5,Results!F5<>Games!$C$9),1,0)) -> 0 | AN18: =IF(OR(G18="",Results!G5=""),"",IF(AND(G18=Results!G5,Results!G5<>Games!$C$10),1,0)) -> 0 | AO18: =IF(OR(H18="",Results!H5=""),"",IF(AND(H18=Results!H5,Results!H5<>Games!$C$11),1,0)) -> 0 | AP18: =IF(OR(I18="",Results!I5=""),"",IF(AND(I18=Results!I5,Results!I5<>Games!$C$12),1,0)) -> 0 | AQ18: =IF(OR(J18="",Results!J5=""),"",IF(AND(J18=Results!J5,Results!J5<>Games!$C$13),1,0)) -> 0 | AR18: =IF(OR(K18="",Results!K5=""),"",IF(AND(K18=Results!K5,Results!K5<>Games!$C$14),1,0)) -> 0 | AS18: =IF(OR(L18="",Results!L5=""),"",IF(AND(L18=Results!L5,Results!L5<>Games!$C$15),1,0)) -> 0 | AT18: =IF(OR(M18="",Results!M5=""),"",IF(AND(M18=Results!M5,Results!M5<>Games!$C$16),1,0)) -> 0 | AU18: =IF(OR(N18="",Results!N5=""),"",IF(AND(N18=Results!N5,Results!N5<>Games!$C$17),1,0)) -> 0 | AV18: =SUM(AI18:AU18) -> 0
A19: =INDEX(Players!$D$6:$D$69,MATCH(26,Players!$A$6:$A$69,0)) -> Dona B. | B19: Georgia Tech | C19: Eastern Michigan | D19: James Madison | E19: Cincinnati | F19: Duke | G19: Auburn | H19: Colorado State | I19: LSU | J19: Hawai'i | K19: UCLA | L19: Western Kentucky | M19: Ole Miss | N19: SMU | O19: 4 | P19: 5 | Q19: 8 | R19: 56 | S19: =IF(OR(B19="",Results!B5=""),"",IF(B19=Results!B5,1+IF(OR($O19=1,$P19=1,$Q19=1),1,0),0)) -> 0 | T19: =IF(OR(C19="",Results!C5=""),"",IF(C19=Results!C5,1+IF(OR($O19=2,$P19=2,$Q19=2),1,0),0)) -> 0 | U19: =IF(OR(D19="",Results!D5=""),"",IF(D19=Results!D5,1+IF(OR($O19=3,$P19=3,$Q19=3),1,0),0)) -> 1 | V19: =IF(OR(E19="",Results!E5=""),"",IF(E19=Results!E5,1+IF(OR($O19=4,$P19=4,$Q19=4),1,0),0)) -> 2 | W19: =IF(OR(F19="",Results!F5=""),"",IF(F19=Results!F5,1+IF(OR($O19=5,$P19=5,$Q19=5),1,0),0)) -> 2 | X19: =IF(OR(G19="",Results!G5=""),"",IF(G19=Results!G5,1+IF(OR($O19=6,$P19=6,$Q19=6),1,0),0)) -> 1 | Y19: =IF(OR(H19="",Results!H5=""),"",IF(H19=Results!H5,1+IF(OR($O19=7,$P19=7,$Q19=7),1,0),0)) -> 1 | Z19: =IF(OR(I19="",Results!I5=""),"",IF(I19=Results!I5,1+IF(OR($O19=8,$P19=8,$Q19=8),1,0),0)) -> 2 | AA19: =IF(OR(J19="",Results!J5=""),"",IF(J19=Results!J5,1+IF(OR($O19=9,$P19=9,$Q19=9),1,0),0)) -> 0 | AB19: =IF(OR(K19="",Results!K5=""),"",IF(K19=Results!K5,1+IF(OR($O19=10,$P19=10,$Q19=10),1,0),0)) -> 1 | AC19: =IF(OR(L19="",Results!L5=""),"",IF(L19=Results!L5,1+IF(OR($O19=11,$P19=11,$Q19=11),1,0),0)) -> 0 | AD19: =IF(OR(M19="",Results!M5=""),"",IF(M19=Results!M5,1+IF(OR($O19=12,$P19=12,$Q19=12),1,0),0)) -> 1 | AE19: =IF(OR(N19="",Results!N5=""),"",IF(N19=Results!N5,1+IF(OR($O19=13,$P19=13,$Q19=13),1,0),0)) -> 1 | AF19: =SUM(S19:AE19) -> 12 | AG19: =IF(OR($R19="",Results!O5=""),"",ABS($R19-Results!O5)) -> 5 | AH19: 26 | AI19: =IF(OR(B19="",Results!B5=""),"",IF(AND(B19=Results!B5,Results!B5<>Games!$C$5),1,0)) -> 0 | AJ19: =IF(OR(C19="",Results!C5=""),"",IF(AND(C19=Results!C5,Results!C5<>Games!$C$6),1,0)) -> 0 | AK19: =IF(OR(D19="",Results!D5=""),"",IF(AND(D19=Results!D5,Results!D5<>Games!$C$7),1,0)) -> 0 | AL19: =IF(OR(E19="",Results!E5=""),"",IF(AND(E19=Results!E5,Results!E5<>Games!$C$8),1,0)) -> 0 | AM19: =IF(OR(F19="",Results!F5=""),"",IF(AND(F19=Results!F5,Results!F5<>Games!$C$9),1,0)) -> 0 | AN19: =IF(OR(G19="",Results!G5=""),"",IF(AND(G19=Results!G5,Results!G5<>Games!$C$10),1,0)) -> 0 | AO19: =IF(OR(H19="",Results!H5=""),"",IF(AND(H19=Results!H5,Results!H5<>Games!$C$11),1,0)) -> 0 | AP19: =IF(OR(I19="",Results!I5=""),"",IF(AND(I19=Results!I5,Results!I5<>Games!$C$12),1,0)) -> 0 | AQ19: =IF(OR(J19="",Results!J5=""),"",IF(AND(J19=Results!J5,Results!J5<>Games!$C$13),1,0)) -> 0 | AR19: =IF(OR(K19="",Results!K5=""),"",IF(AND(K19=Results!K5,Results!K5<>Games!$C$14),1,0)) -> 0 | AS19: =IF(OR(L19="",Results!L5=""),"",IF(AND(L19=Results!L5,Results!L5<>Games!$C$15),1,0)) -> 0 | AT19: =IF(OR(M19="",Results!M5=""),"",IF(AND(M19=Results!M5,Results!M5<>Games!$C$16),1,0)) -> 0 | AU19: =IF(OR(N19="",Results!N5=""),"",IF(AND(N19=Results!N5,Results!N5<>Games!$C$17),1,0)) -> 0 | AV19: =SUM(AI19:AU19) -> 0
A20: =INDEX(Players!$D$6:$D$69,MATCH(52,Players!$A$6:$A$69,0)) -> Dylan G. | B20: Georgia Tech | C20: San Jose State | D20: James Madison | E20: Cincinnati | F20: Duke | G20: Auburn | H20: Colorado State | I20: LSU | J20: UNLV | K20: UCLA | L20: Nevada | M20: Ole Miss | N20: SMU | O20: 1 | P20: 4 | Q20: 8 | R20: 48 | S20: =IF(OR(B20="",Results!B5=""),"",IF(B20=Results!B5,1+IF(OR($O20=1,$P20=1,$Q20=1),1,0),0)) -> 0 | T20: =IF(OR(C20="",Results!C5=""),"",IF(C20=Results!C5,1+IF(OR($O20=2,$P20=2,$Q20=2),1,0),0)) -> 1 | U20: =IF(OR(D20="",Results!D5=""),"",IF(D20=Results!D5,1+IF(OR($O20=3,$P20=3,$Q20=3),1,0),0)) -> 1 | V20: =IF(OR(E20="",Results!E5=""),"",IF(E20=Results!E5,1+IF(OR($O20=4,$P20=4,$Q20=4),1,0),0)) -> 2 | W20: =IF(OR(F20="",Results!F5=""),"",IF(F20=Results!F5,1+IF(OR($O20=5,$P20=5,$Q20=5),1,0),0)) -> 1 | X20: =IF(OR(G20="",Results!G5=""),"",IF(G20=Results!G5,1+IF(OR($O20=6,$P20=6,$Q20=6),1,0),0)) -> 1 | Y20: =IF(OR(H20="",Results!H5=""),"",IF(H20=Results!H5,1+IF(OR($O20=7,$P20=7,$Q20=7),1,0),0)) -> 1 | Z20: =IF(OR(I20="",Results!I5=""),"",IF(I20=Results!I5,1+IF(OR($O20=8,$P20=8,$Q20=8),1,0),0)) -> 2 | AA20: =IF(OR(J20="",Results!J5=""),"",IF(J20=Results!J5,1+IF(OR($O20=9,$P20=9,$Q20=9),1,0),0)) -> 1 | AB20: =IF(OR(K20="",Results!K5=""),"",IF(K20=Results!K5,1+IF(OR($O20=10,$P20=10,$Q20=10),1,0),0)) -> 1 | AC20: =IF(OR(L20="",Results!L5=""),"",IF(L20=Results!L5,1+IF(OR($O20=11,$P20=11,$Q20=11),1,0),0)) -> 1 | AD20: =IF(OR(M20="",Results!M5=""),"",IF(M20=Results!M5,1+IF(OR($O20=12,$P20=12,$Q20=12),1,0),0)) -> 1 | AE20: =IF(OR(N20="",Results!N5=""),"",IF(N20=Results!N5,1+IF(OR($O20=13,$P20=13,$Q20=13),1,0),0)) -> 1 | AF20: =SUM(S20:AE20) -> 14 | AG20: =IF(OR($R20="",Results!O5=""),"",ABS($R20-Results!O5)) -> 3 | AH20: 52 | AI20: =IF(OR(B20="",Results!B5=""),"",IF(AND(B20=Results!B5,Results!B5<>Games!$C$5),1,0)) -> 0 | AJ20: =IF(OR(C20="",Results!C5=""),"",IF(AND(C20=Results!C5,Results!C5<>Games!$C$6),1,0)) -> 1 | AK20: =IF(OR(D20="",Results!D5=""),"",IF(AND(D20=Results!D5,Results!D5<>Games!$C$7),1,0)) -> 0 | AL20: =IF(OR(E20="",Results!E5=""),"",IF(AND(E20=Results!E5,Results!E5<>Games!$C$8),1,0)) -> 0 | AM20: =IF(OR(F20="",Results!F5=""),"",IF(AND(F20=Results!F5,Results!F5<>Games!$C$9),1,0)) -> 0 | AN20: =IF(OR(G20="",Results!G5=""),"",IF(AND(G20=Results!G5,Results!G5<>Games!$C$10),1,0)) -> 0 | AO20: =IF(OR(H20="",Results!H5=""),"",IF(AND(H20=Results!H5,Results!H5<>Games!$C$11),1,0)) -> 0 | AP20: =IF(OR(I20="",Results!I5=""),"",IF(AND(I20=Results!I5,Results!I5<>Games!$C$12),1,0)) -> 0 | AQ20: =IF(OR(J20="",Results!J5=""),"",IF(AND(J20=Results!J5,Results!J5<>Games!$C$13),1,0)) -> 0 | AR20: =IF(OR(K20="",Results!K5=""),"",IF(AND(K20=Results!K5,Results!K5<>Games!$C$14),1,0)) -> 0 | AS20: =IF(OR(L20="",Results!L5=""),"",IF(AND(L20=Results!L5,Results!L5<>Games!$C$15),1,0)) -> 1 | AT20: =IF(OR(M20="",Results!M5=""),"",IF(AND(M20=Results!M5,Results!M5<>Games!$C$16),1,0)) -> 0 | AU20: =IF(OR(N20="",Results!N5=""),"",IF(AND(N20=Results!N5,Results!N5<>Games!$C$17),1,0)) -> 0 | AV20: =SUM(AI20:AU20) -> 2
A21: =INDEX(Players!$D$6:$D$69,MATCH(9,Players!$A$6:$A$69,0)) -> Evan H. | B21: Georgia Tech | C21: San Jose State | D21: James Madison | E21: Cincinnati | F21: Duke | G21: Auburn | H21: Colorado State | I21: LSU | J21: Hawai'i | K21: UCLA | L21: Western Kentucky | M21: Louisville | N21: SMU | O21: 1 | P21: 5 | Q21: 10 | R21: 42 | S21: =IF(OR(B21="",Results!B5=""),"",IF(B21=Results!B5,1+IF(OR($O21=1,$P21=1,$Q21=1),1,0),0)) -> 0 | T21: =IF(OR(C21="",Results!C5=""),"",IF(C21=Results!C5,1+IF(OR($O21=2,$P21=2,$Q21=2),1,0),0)) -> 1 | U21: =IF(OR(D21="",Results!D5=""),"",IF(D21=Results!D5,1+IF(OR($O21=3,$P21=3,$Q21=3),1,0),0)) -> 1 | V21: =IF(OR(E21="",Results!E5=""),"",IF(E21=Results!E5,1+IF(OR($O21=4,$P21=4,$Q21=4),1,0),0)) -> 1 | W21: =IF(OR(F21="",Results!F5=""),"",IF(F21=Results!F5,1+IF(OR($O21=5,$P21=5,$Q21=5),1,0),0)) -> 2 | X21: =IF(OR(G21="",Results!G5=""),"",IF(G21=Results!G5,1+IF(OR($O21=6,$P21=6,$Q21=6),1,0),0)) -> 1 | Y21: =IF(OR(H21="",Results!H5=""),"",IF(H21=Results!H5,1+IF(OR($O21=7,$P21=7,$Q21=7),1,0),0)) -> 1 | Z21: =IF(OR(I21="",Results!I5=""),"",IF(I21=Results!I5,1+IF(OR($O21=8,$P21=8,$Q21=8),1,0),0)) -> 1 | AA21: =IF(OR(J21="",Results!J5=""),"",IF(J21=Results!J5,1+IF(OR($O21=9,$P21=9,$Q21=9),1,0),0)) -> 0 | AB21: =IF(OR(K21="",Results!K5=""),"",IF(K21=Results!K5,1+IF(OR($O21=10,$P21=10,$Q21=10),1,0),0)) -> 2 | AC21: =IF(OR(L21="",Results!L5=""),"",IF(L21=Results!L5,1+IF(OR($O21=11,$P21=11,$Q21=11),1,0),0)) -> 0 | AD21: =IF(OR(M21="",Results!M5=""),"",IF(M21=Results!M5,1+IF(OR($O21=12,$P21=12,$Q21=12),1,0),0)) -> 0 | AE21: =IF(OR(N21="",Results!N5=""),"",IF(N21=Results!N5,1+IF(OR($O21=13,$P21=13,$Q21=13),1,0),0)) -> 1 | AF21: =SUM(S21:AE21) -> 11 | AG21: =IF(OR($R21="",Results!O5=""),"",ABS($R21-Results!O5)) -> 9 | AH21: 9 | AI21: =IF(OR(B21="",Results!B5=""),"",IF(AND(B21=Results!B5,Results!B5<>Games!$C$5),1,0)) -> 0 | AJ21: =IF(OR(C21="",Results!C5=""),"",IF(AND(C21=Results!C5,Results!C5<>Games!$C$6),1,0)) -> 1 | AK21: =IF(OR(D21="",Results!D5=""),"",IF(AND(D21=Results!D5,Results!D5<>Games!$C$7),1,0)) -> 0 | AL21: =IF(OR(E21="",Results!E5=""),"",IF(AND(E21=Results!E5,Results!E5<>Games!$C$8),1,0)) -> 0 | AM21: =IF(OR(F21="",Results!F5=""),"",IF(AND(F21=Results!F5,Results!F5<>Games!$C$9),1,0)) -> 0 | AN21: =IF(OR(G21="",Results!G5=""),"",IF(AND(G21=Results!G5,Results!G5<>Games!$C$10),1,0)) -> 0 | AO21: =IF(OR(H21="",Results!H5=""),"",IF(AND(H21=Results!H5,Results!H5<>Games!$C$11),1,0)) -> 0 | AP21: =IF(OR(I21="",Results!I5=""),"",IF(AND(I21=Results!I5,Results!I5<>Games!$C$12),1,0)) -> 0 | AQ21: =IF(OR(J21="",Results!J5=""),"",IF(AND(J21=Results!J5,Results!J5<>Games!$C$13),1,0)) -> 0 | AR21: =IF(OR(K21="",Results!K5=""),"",IF(AND(K21=Results!K5,Results!K5<>Games!$C$14),1,0)) -> 0 | AS21: =IF(OR(L21="",Results!L5=""),"",IF(AND(L21=Results!L5,Results!L5<>Games!$C$15),1,0)) -> 0 | AT21: =IF(OR(M21="",Results!M5=""),"",IF(AND(M21=Results!M5,Results!M5<>Games!$C$16),1,0)) -> 0 | AU21: =IF(OR(N21="",Results!N5=""),"",IF(AND(N21=Results!N5,Results!N5<>Games!$C$17),1,0)) -> 0 | AV21: =SUM(AI21:AU21) -> 1
